<?xml version="1.0" encoding="utf-8"?>
<mujoco>
    <compiler angle="radian" coordinate="local"/>
    <option timestep="0.002" iterations="20" apirate="200">
        <flag warmstart="enable"/>
    </option>

    <size njmax="500" nconmax="100" nuser_jnt="1" nuser_site="1" nuser_tendon="1" nuser_sensor="1" nuser_actuator="16"
          nstack="600000"/>

    <visual>
        <map fogstart="3" fogend="5" force="0.1"></map>
        <quality shadowsize="4096"></quality>
    </visual>

    <default>
        <default class="robot0:asset_class">
            <geom friction="1 0.5 0.1" condim="6" contype="1" conaffinity="1"></geom>
            <joint limited="true" damping="0.1" armature="0.001" margin="0.01" frictionloss="0.001"></joint>
            <site size="0.005" rgba="0.4 0.9 0.4 1"></site>
            <general ctrllimited="true" forcelimited="true"></general>
        </default>
        <default class="robot0:D_Touch">
            <site type="box" size="0.009 0.004 0.013" pos="0 -0.004 0.018" rgba="0.8 0.8 0.8 0.15" group="4"></site>
        </default>
        <default class="robot0:DC_Hand">
            <geom material="robot0:MatColl" contype="1" conaffinity="0" group="4"></geom>
        </default>
        <default class="robot0:D_Vizual">
            <geom material="robot0:MatViz" contype="0" conaffinity="0" group="1" type="mesh"></geom>
        </default>
        <default class="robot0:free">
            <joint type="free" damping="0" armature="0" limited="false"></joint>
        </default>
    </default>

    <contact>
        <pair geom1="robot0:C_FF1" geom2="robot0:C_TH1" condim="1"></pair>
        <pair geom1="robot0:C_FF2" geom2="robot0:C_TH1" condim="1"></pair>
        <pair geom1="robot0:C_FF3" geom2="robot0:C_TH1" condim="1"></pair>
        <pair geom1="robot0:C_MF3" geom2="robot0:C_TH1" condim="1"></pair>
        <pair geom1="robot0:C_MF1" geom2="robot0:C_TH1" condim="1"></pair>
        <pair geom1="robot0:C_RF1" geom2="robot0:C_TH1" condim="1"></pair>
        <pair geom1="robot0:C_LF1" geom2="robot0:C_TH1" condim="1"></pair>
        <pair geom1="robot0:C_palm0" geom2="robot0:C_TH1" condim="1"></pair>
        <pair geom1="robot0:C_MF1" geom2="robot0:C_FF1" condim="1"></pair>
        <pair geom1="robot0:C_RF1" geom2="robot0:C_MF1" condim="1"></pair>
        <pair geom1="robot0:C_LF1" geom2="robot0:C_RF1" condim="1"></pair>
        <pair geom1="robot0:C_MF3" geom2="robot0:C_FF3" condim="1"></pair>
        <pair geom1="robot0:C_RF3" geom2="robot0:C_MF3" condim="1"></pair>
        <pair geom1="robot0:C_LF3" geom2="robot0:C_RF3" condim="1"></pair>
        <pair geom1="robot0:C_LF1" geom2="robot0:C_RF1" condim="1"></pair>
        <pair geom1="robot0:C_LF1" geom2="robot0:C_MF1" condim="1"></pair>
        <pair geom1="robot0:C_LF1" geom2="robot0:C_RF2" condim="1"></pair>
        <pair geom1="robot0:C_LF2" geom2="robot0:C_RF1" condim="1"></pair>
        <pair geom1="robot0:C_LF2" geom2="robot0:C_RF2" condim="1"></pair>
    </contact>

    <actuator>
        <motor gear="1" name="robot0:A_slide0" joint="robot0:slide0"></motor>
        <motor gear="1" name="robot0:A_slide1" joint="robot0:slide1"></motor>
        <motor gear="1" name="robot0:A_slide2" joint="robot0:slide2"></motor>
        <motor gear="1" name="robot0:A_WRJ0" user="2036" joint="robot0:WRJ0"></motor>
        <motor gear="1" name="robot0:A_WRJ1" user="2038" joint="robot0:WRJ1"></motor>
        <motor gear="1" name="robot0:A_WRJ2" user="1984" joint="robot0:WRJ2"></motor>
        <motor gear="1" name="robot0:A_FFJ3y" user="2004" joint="robot0:FFJ3y"></motor>
        <motor gear="1" name="robot0:A_FFJ3z" user="2004" joint="robot0:FFJ3z"></motor>
        <motor gear="1" name="robot0:A_FFJ2z" user="2004" joint="robot0:FFJ2z"></motor>
        <motor gear="1" name="robot0:A_FFJ1z" user="2004" joint="robot0:FFJ1z"></motor>
        <motor gear="1" name="robot0:A_MFJ3y" user="2004" joint="robot0:MFJ3y"></motor>
        <motor gear="1" name="robot0:A_MFJ3z" user="2004" joint="robot0:MFJ3z"></motor>
        <motor gear="1" name="robot0:A_MFJ2z" user="2004" joint="robot0:MFJ2z"></motor>
        <motor gear="1" name="robot0:A_MFJ1z" user="2004" joint="robot0:MFJ1z"></motor>
        <motor gear="1" name="robot0:A_LFJ3y" user="2004" joint="robot0:LFJ3y"></motor>
        <motor gear="1" name="robot0:A_LFJ3z" user="2004" joint="robot0:LFJ3z"></motor>
        <motor gear="1" name="robot0:A_LFJ2z" user="2004" joint="robot0:LFJ2z"></motor>
        <motor gear="1" name="robot0:A_LFJ1z" user="2004" joint="robot0:LFJ1z"></motor>
        <motor gear="1" name="robot0:A_RFJ3y" user="2004" joint="robot0:RFJ3y"></motor>
        <motor gear="1" name="robot0:A_RFJ3z" user="2004" joint="robot0:RFJ3z"></motor>
        <motor gear="1" name="robot0:A_RFJ2z" user="2004" joint="robot0:RFJ2z"></motor>
        <motor gear="1" name="robot0:A_RFJ1z" user="2004" joint="robot0:RFJ1z"></motor>
        <motor gear="1" name="robot0:A_THJ3x" user="2004" joint="robot0:THJ3x"></motor>
        <motor gear="1" name="robot0:A_THJ3y" user="2004" joint="robot0:THJ3y"></motor>
        <motor gear="1" name="robot0:A_THJ3z" user="2004" joint="robot0:THJ3z"></motor>
        <motor gear="1" name="robot0:A_THJ2x" user="2004" joint="robot0:THJ2x"></motor>
        <motor gear="1" name="robot0:A_THJ2y" user="2004" joint="robot0:THJ2y"></motor>
        <motor gear="1" name="robot0:A_THJ2z" user="2004" joint="robot0:THJ2z"></motor>
        <motor gear="1" name="robot0:A_THJ1y" user="2004" joint="robot0:THJ1y"></motor>

    </actuator>

    <asset>
        <texture type="skybox" builtin="gradient" rgb1="0.44 0.85 0.56" rgb2="0.46 0.87 0.58" width="32" height="32"/>

        <texture name="robot0:texplane" type="2d" builtin="checker" rgb1="0.2 0.3 0.4" rgb2="0.1 0.15 0.2" width="512"
                 height="512"/>
        <texture name="robot0:texgeom" type="cube" builtin="flat" mark="cross" width="127" height="127" rgb1="0.3 0.6 0.5"
                 rgb2="0.3 0.6 0.5" markrgb="0 0 0" random="0.01"/>

        <material name="robot0:MatGnd" reflectance="0.5" texture="robot0:texplane" texrepeat="1 1" texuniform="true"/>
        <material name="robot0:MatColl" specular="1" shininess="0.3" reflectance="0.5" rgba="0.4 0.5 0.6 1"/>
        <material name="robot0:MatViz" specular="0.75" shininess="0.1" reflectance="0.5" rgba="0.93 0.93 0.93 1"/>
        <material name="robot0:object" texture="robot0:texgeom" texuniform="false"/>
        <material name="floor_mat" specular="0" shininess="0.5" reflectance="0" rgba="0.2 0.2 0.2 0"/>
        <material name="MatPlane" reflectance="0.5" shininess="1" specular="1" texrepeat="60 60" texture="robot0:texplane"/>

        <mesh name="palm" file="../stls/manohand/palm_mean.stl"/>
        <mesh name="ffdist" file="../stls/manohand/ffdist_mean.stl"/>
        <mesh name="ffmiddle" file="../stls/manohand/ffmiddle_mean.stl"/>
        <mesh name="ffprox" file="../stls/manohand/ffprox_mean.stl"/>
        <mesh name="lfdist" file="../stls/manohand/lfdist_mean.stl"/>
        <mesh name="lfmiddle" file="../stls/manohand/lfmiddle_mean.stl"/>
        <mesh name="lfprox" file="../stls/manohand/lfprox_mean.stl"/>
        <mesh name="mfdist" file="../stls/manohand/mfdist_mean.stl"/>
        <mesh name="mfmiddle" file="../stls/manohand/mfmiddle_mean.stl"/>
        <mesh name="mfprox" file="../stls/manohand/mfprox_mean.stl"/>
        <mesh name="rfdist" file="../stls/manohand/rfdist_mean.stl"/>
        <mesh name="rfmiddle" file="../stls/manohand/rfmiddle_mean.stl"/>
        <mesh name="rfprox" file="../stls/manohand/rfprox_mean.stl"/>
        <mesh name="thdist" file="../stls/manohand/thdist_mean.stl"/>
        <mesh name="thmiddle" file="../stls/manohand/thmiddle_mean.stl"/>
        <mesh name="thprox" file="../stls/manohand/thprox_mean.stl"/>
    </asset>

    <worldbody>
        <geom conaffinity="1" condim="3" name="floor" pos="0 0 0" rgba="0.8 0.9 0.8 1" size="100 100 .2" type="plane" material="MatPlane"/>
        <body name="table">
            <geom name="C_Table" type="box" size="0.8 0.8 0.25" rgba="0.8 0.9 0.8 1" pos="0 0 0.25" condim="4" contype="1" conaffinity="0" />
        </body>
        <body name="handworld" pos="0 0 0" euler="0 0 0">
            <body name="link_palm" pos="0 0 0" euler="0 0 0" childclass="robot0:asset_class">
                <joint name="robot0:slide0" type="slide" pos="0 0 0" axis="1 0 0" range="-2.0 2.0" armature="0.005"></joint>
                <joint name="robot0:slide1" type="slide" pos="0 0 0" axis="0 1 0" range="-2.0 2.0" armature="0.005"></joint>
                <joint name="robot0:slide2" type="slide" pos="0 0 0" axis="0 0 1" range="0.2 2.0" armature="0.005"></joint>
                <joint name="robot0:WRJ0" type="hinge" pos="0 0 0" axis="1 0 0" range="-3.14 3.14" armature="0.005" user="1123"></joint>
                <joint name="robot0:WRJ1" type="hinge" pos="0 0 0" axis="0 1 0" range="-1.57 1.57" armature="0.005" user="1123"></joint>
                <joint name="robot0:WRJ2" type="hinge" pos="0 0 0" axis="0 0 1" range="-3.14 3.14" armature="0.005" user="1123"></joint>
                <inertial pos="-0.03 0 0" euler="0 0 0.2" mass="0.3" diaginertia="0.001 0.001 0.001"/>
                <geom class="robot0:D_Vizual" name="robot0:V_palm" mesh="palm"></geom>
                <geom class="robot0:DC_Hand" name="robot0:C_palm0" type="box" pos="-0.03 0 0" size="0.0439 0.0135 0.035" euler="0 0 0.2"></geom>
                <geom class="robot0:DC_Hand" name="robot0:C_palm1" type="capsule" euler="-2.61505 0.70030 -1.87000" pos="-0.01187 -0.00708 0.01218" size="0.015 0.01842"></geom>
                <body name="link_ff_pm" pos="-0.0880972 -0.00520036 0.020686">
                    <joint name="robot0:FFJ3y" type="hinge" pos="0 0 0" axis="0 1 0" range="-1.0 1.0" armature="0.005" user="1123"></joint>
                    <joint name="robot0:FFJ3z" type="hinge" pos="0 0 0" axis="0 0 1" range="-0.3 1.57" armature="0.005" user="1123"></joint>
                    <inertial pos="-0.01633945  0.00200468  0.0011085" euler="2.0759187  1.43150624 1.94972864" mass="0.014" diaginertia="1e-05 1e-05 1e-05"></inertial>
                    <geom class="robot0:D_Vizual" name="robot0:V_FF3" mesh="ffprox"></geom>
                    <geom class="robot0:DC_Hand" name="robot0:C_FF3" type="capsule" pos="-0.01633945  0.00200468  0.0011085" size="0.009 0.0165" euler="2.0759187  1.43150624 1.94972864"></geom>
                    <body name="link_ff_md" pos="-0.0326789 0.00400935 0.00221706">
                        <inertial pos="-1.10779554e-02 -6.49210764e-04 -5.70546836e-05" euler="-1.48313839 1.51203433 -1.42475203" mass="0.012" diaginertia="1e-05 1e-05 1e-05"></inertial>
                        <joint name="robot0:FFJ2z" type="hinge" pos="0 0 0" axis="0 0 1" range="-0.5 1.57" armature="0.005" user="1123"></joint>
                        <geom class="robot0:D_Vizual" name="robot0:V_FF2" mesh="ffmiddle"></geom>
                        <geom class="robot0:DC_Hand" name="robot0:C_FF2" type="capsule" pos="-1.10779554e-02 -6.49210764e-04 -5.70546836e-05" size="0.0075 0.0111" euler="-1.48313839 1.51203433 -1.42475203"></geom>
                        <body name="link_ff_dd" pos="-0.0221559 -0.00129842 -0.000114109">
                            <inertial pos="-0.01163138  0.00035898  0.00202463" euler="2.96610898 1.39582282 2.93259132" mass="0.01" diaginertia="1e-05 1e-05 1e-05"></inertial>
                            <joint name="robot0:FFJ1z" type="hinge" pos="0 0 0" axis="0 0 1" range="0 1.57" armature="0.005" user="1123"></joint>
                            <geom class="robot0:D_Vizual" name="robot0:V_FF1" mesh="ffdist"></geom>
                            <geom class="robot0:DC_Hand" name="robot0:C_FF1" type="capsule" pos="-0.01163138  0.00035898  0.00202463" size="0.0075 0.0075" euler="2.96610898 1.39582282 2.93259132"></geom>
                        </body>
                    </body>
                </body>
                <body name="link_mf_pm" pos="-0.0946604 -0.00147896 -0.00335754">
                    <inertial pos="-0.01559134  0.00093066 -0.00279725" euler="0.32118629 1.38392244 0.26686409" mass="0.014" diaginertia="1e-05 1e-05 1e-05"></inertial>
                    <joint name="robot0:MFJ3y" type="hinge" pos="0 0 0" axis="0 1 0" range="-1.0 1.0" armature="0.005" user="1123"></joint>
                    <joint name="robot0:MFJ3z" type="hinge" pos="0 0 0" axis="0 0 1" range="0 1.57" armature="0.005" user="1123"></joint>
                    <geom class="robot0:D_Vizual" name="robot0:V_MF3" mesh="mfprox"></geom>
                    <geom class="robot0:DC_Hand" name="robot0:C_MF3" type="capsule" pos="-0.01559134  0.00093066 -0.00279725" size="0.009 0.0158675" euler="0.32118629 1.38392244 0.26686409"></geom>
                    <body name="link_mf_md" pos="-0.0311827 0.00186133 -0.00559451">
                        <inertial pos="-0.01145232 -0.00062605 -0.001972263" euler="-0.30736925 1.39204219 -0.25742004" mass="0.012" diaginertia="1e-05 1e-05 1e-05"></inertial>
                        <joint name="robot0:MFJ2z" type="hinge" pos="0 0 0" axis="0 0 1" range="0 1.57" armature="0.005" user="1123"></joint>
                        <geom class="robot0:D_Vizual" name="robot0:V_MF2" mesh="mfmiddle"></geom>
                        <geom class="robot0:DC_Hand" name="robot0:C_MF2" type="capsule" pos="-0.01145232 -0.00062605 -0.001972263" size="0.0075 0.01163" euler="-0.30736925 1.39204219 -0.25742004"></geom>
                        <body name="link_mf_dd" pos="-0.0229046 -0.0012521 -0.00394452">
                            <inertial pos="-0.01551503 -0.00070755 -0.00318577" euler="-0.21855015 1.36348088  -0.17760409" mass="0.01" diaginertia="1e-05 1e-05 1e-05"></inertial>
                            <joint name="robot0:MFJ1z" type="hinge" pos="0 0 0" axis="0 0 1" range="0 1.57" armature="0.005" user="1123"></joint>
                            <geom class="robot0:D_Vizual" name="robot0:V_MF1" mesh="mfdist"></geom>
                            <geom class="robot0:DC_Hand" name="robot0:C_MF1" type="capsule" pos="-0.01551503 -0.00070755 -0.00318577" size="0.0075 0.005" euler="-0.21855015 1.36348088  -0.17760409"></geom>
                        </body>
                    </body>
                </body>
                <body name="link_lf_pm" pos="-0.0687869 -0.00994033 -0.0432093">
                    <joint name="robot0:LFJ3y" type="hinge" pos="0 0 0" axis="0 1 0" range="-1.0 1.0" armature="0.005" user="1123"></joint>
                    <inertial pos="-8.50720331e-03  3.09124589e-05 -6.24939241e-03" euler="0.00494643 0.93721839 0.00250398" mass="0.07" diaginertia="0.0005 0.0005 0.0005"/>
                    <joint name="robot0:LFJ3z" type="hinge" pos="0 0 0" axis="0 0 1" range="0 1.57" armature="0.005" user="1123"></joint>
                    <geom class="robot0:D_Vizual" name="robot0:V_LF3" mesh="lfprox"></geom>
                    <geom class="robot0:DC_Hand" name="robot0:C_LF3" type="capsule" pos="-8.50720331e-03  3.09124589e-05 -6.24939241e-03" size="0.009 0.010555964" euler="0.00494643 0.93721839 0.00250398"></geom>
                    <body name="link_lf_md" pos="-0.0170144 6.18249e-05 -0.0124988">
                        <inertial pos="-0.00793345 -0.00034558 -0.00516596" euler="-0.06679566 0.99258405 -0.0361792" mass="0.06" diaginertia="0.0005 0.0005 0.0005"/>
                        <joint name="robot0:LFJ2z" type="hinge" pos="0 0 0" axis="0 0 1" range="0 1.57" armature="0.005" user="1123"></joint>
                        <geom class="robot0:D_Vizual" name="robot0:V_LF2" mesh="lfmiddle"></geom>
                        <geom class="robot0:DC_Hand" name="robot0:C_LF2" type="capsule" pos="-0.00793345 -0.00034558 -0.00516596" size="0.0075 0.009473446" euler="-0.06679566 0.99258405 -0.0361792"></geom>
                        <body name="link_lf_dd" pos="-0.0158669 -0.000691155 -0.0103319">
                            <inertial pos="-0.00977975  0.00129545 -0.00574058" euler="0.22194785 1.02909336 0.12582808" mass="0.05" diaginertia="0.0005 0.0005 0.0005"/>
                            <joint name="robot0:LFJ1z" type="hinge" pos="0 0 0" axis="0 0 1" range="0 1.57" armature="0.005" user="1123"></joint>
                            <geom class="robot0:D_Vizual" name="robot0:V_LF1" mesh="lfdist"></geom>
                            <geom class="robot0:DC_Hand" name="robot0:C_LF1" type="capsule" pos="-0.00977975  0.00129545 -0.00574058" size="0.0065 0.0035" euler="0.22194785 1.02909336 0.12582808"></geom>
                        </body>
                    </body>
                </body>
                <body name="link_rf_pm" pos="-0.0817355 -0.00395742 -0.0266732">
                    <joint name="robot0:RFJ3y" type="hinge" pos="0 0 0" axis="0 1 0" range="-1.0 1.0" armature="0.005" user="1123"></joint>
                    <inertial pos="-0.01415714  0.0010335  -0.00254927" euler="0.38516311 1.37888284 0.31878467" mass="0.014" diaginertia="1e-05 1e-05 1e-05"></inertial>
                    <joint name="robot0:RFJ3z" type="hinge" pos="0 0 0" axis="0 0 1" range="0 1.57" armature="0.005" user="1123"></joint>
                    <geom class="robot0:D_Vizual" name="robot0:V_RF3" mesh="rfprox"></geom>
                    <geom class="robot0:DC_Hand" name="robot0:C_RF3" type="capsule" pos="-0.01415714  0.0010335  -0.00254927" size="0.009 0.014421906" euler="0.38516311 1.37888284 0.31878467"></geom>
                    <body name="link_rf_md" pos="-0.0283143 0.00206701 -0.00509854">
                        <inertial pos="-0.01176025 -0.00084406 -0.00381691" euler="-0.21763357 1.24988512 -0.15729772" mass="0.012" diaginertia="1e-05 1e-05 1e-05"></inertial>
                        <joint name="robot0:RFJ2z" type="hinge" pos="0 0 0" axis="0 0 1" range="-0.2 1.57" armature="0.005" user="1123"></joint>
                        <geom class="robot0:D_Vizual" name="robot0:V_RF2" mesh="rfmiddle"></geom>
                        <geom class="robot0:DC_Hand" name="robot0:C_RF2" type="capsule" pos="-0.01176025 -0.00084406 -0.00381691" size="0.0075 0.012392933" euler="-0.21763357 1.24988512 -0.15729772"></geom>
                        <body name="link_rf_dd" pos="-0.0235205 -0.00168811 -0.00763382">
                            <inertial pos="-0.01460212  0.00187106 -0.00404494" euler="0.43325752 1.27456581 0.32302802" mass="0.01" diaginertia="1e-05 1e-05 1e-05"></inertial>
                            <joint name="robot0:RFJ1z" type="hinge" pos="0 0 0" axis="0 0 1" range="0 1.57" armature="0.005" user="1123"></joint>
                            <geom class="robot0:D_Vizual" name="robot0:V_RF1" mesh="rfdist"></geom>
                            <geom class="robot0:DC_Hand" name="robot0:C_RF1" type="capsule" pos="-0.01460212  0.00187106 -0.00404494" size="0.0075 0.005" euler="0.43325752 1.27456581 0.32302802"></geom>
                        </body>
                    </body>
                </body>
                <body name="link_th_pm" pos="-0.0240897 -0.0155223 0.0258128">
                    <joint name="robot0:THJ3x" type="hinge" pos="0 0 0" axis="1 0 0" range="0 1.57" armature="0.005" user="1123"></joint>
                    <joint name="robot0:THJ3y" type="hinge" pos="0 0 0" axis="0 1 0" range="-1.0 1.0" armature="0.005" user="1123"></joint>
                    <inertial pos="-0.00981662  0.00044564  0.01184977" euler="3.10400265 0.69148607 3.03731965" mass="0.016" diaginertia="1e-05 1e-05 1e-05"></inertial>
                    <joint name="robot0:THJ3z" type="hinge" pos="0 0 0" axis="0 0 1" range="-0.25 2.0" armature="0.005" user="1123"></joint>
                    <geom class="robot0:D_Vizual" name="robot0:V_TH3" mesh="thprox"></geom>
                    <geom class="robot0:DC_Hand" name="robot0:C_TH3" type="capsule" pos="-0.00981662  0.00044564  0.01184977" size="0.01 0.015394214" euler="3.10400265 0.69148607 3.03731965"></geom>
                    <body name="link_th_md" pos="-0.0196332 0.000891286 0.0236995">
                        <joint name="robot0:THJ2x" type="hinge" pos="0 0 0" axis="1 0 0" range="-1 1" armature="0.005" user="1123"></joint>
                        <joint name="robot0:THJ2y" type="hinge" pos="0 0 0" axis="0 1 0" range="-0.5 0.5" armature="0.005" user="1123"></joint>
                        <inertial pos="-0.01110887 -0.00271648  0.00726206" euler="-2.78364168 0.96144328  -2.47379542" mass="0.014" diaginertia="1e-05 1e-05 1e-05"></inertial>
                        <joint name="robot0:THJ2z" type="hinge" pos="0 0 0" axis="0 0 1" range="-0.5 0.5" armature="0.005" user="1123"></joint>
                        <geom class="robot0:D_Vizual" name="robot0:V_TH2" mesh="thmiddle"></geom>
                        <geom class="robot0:DC_Hand" name="robot0:C_TH2" type="capsule" pos="-0.01110887 -0.00271648  0.00726206" size="0.01 0.013547092" euler="-2.78364168 0.96144328  -2.47379542"></geom>
                        <body name="link_th_dd" pos="-0.0222177 -0.00543297 0.0145241">
                            <joint name="robot0:THJ1y" type="hinge" pos="0 0 0" axis="0 1 0" range="-1 1" armature="0.005" user="1123"></joint>
                            <inertial pos="-0.01577465 -0.00326327  0.01024323" euler="-2.83317999 0.97259243  -2.56963586" mass="0.012" diaginertia="1e-05 1e-05 1e-05"></inertial>
                            <geom class="robot0:D_Vizual" name="robot0:V_TH1" mesh="thdist"></geom>
                            <geom class="robot0:DC_Hand" name="robot0:C_TH1" type="capsule" pos="-0.01577465 -0.00326327  0.01024323" size="0.01 0.01" euler="-2.83317999 0.97259243  -2.56963586"></geom>
                        </body>
                    </body>
                </body>
            </body>
        </body>
        <light directional="true" ambient="0.2 0.2 0.2" diffuse="0.8 0.8 0.8" specular="0.3 0.3 0.3" castshadow="false"
               pos="0 1 4" dir="0 0 -1" name="light0"/>
    </worldbody>
</mujoco>
